Workbook

Sheet 男生名單
A1: 男生名單
A2: 序號 | B2: 姓名 | C2: 姓 | D2: 名1 | E2: 名2 | F2: 姓劃 | G2: 名1劃 | H2: 名2劃 | I2: 天格 | J2: 人格 | K2: 地格 | L2: 外格 | M2: 總格 | N2: 五格判定 | O2: 三才配置 | P2: 天人關係 | Q2: 人地關係 | R2: 三才吉凶 | S2: 姓部首五行 | T2: 名1部首五行 | U2: 名2部首五行 | V2: 名字補五行 | W2: 字義寓意
A3: 1 | B3: 李秉哲 | C3: 李 | D3: 秉 | E3: 哲 | F3: 7 | G3: 8 | H3: 10 | I3: =F3+1 -> 8 | J3: =F3+G3 -> 15 | K3: =G3+H3 -> 18 | L3: =H3+1 -> 11 | M3: =F3+G3+H3 -> 25 | N3: =IF(COUNTIF(規則與試算!$A$14:$A$46,I3)+COUNTIF(規則與試算!$A$14:$A$46,J3)+COUNTIF(規則與試算!$A$14:$A$46,K3)+COUNTIF(規則與試算!$A$14:$A$46,L3)+COUNTIF(規則與試算!$A$14:$A$46,M3)=5,"全吉","有凶") -> 全吉 | O3: =INDEX(規則與試算!$D$14:$D$23,MOD(I3,10)+1)&INDEX(規則與試算!$D$14:$D$23,MOD(J3,10)+1)&INDEX(規則與試算!$D$14:$D$23,MOD(K3,10)+1) -> 金土金 | P3: =INDEX(規則與試算!$G$14:$G$38,MATCH(MID(O3,1,1)&MID(O3,2,1),規則與試算!$F$14:$F$38,0)) -> 生 | Q3: =INDEX(規則與試算!$G$14:$G$38,MATCH(MID(O3,2,1)&MID(O3,3,1),規則與試算!$F$14:$F$38,0)) -> 生 | R3: =IF(AND(P3<>"剋",Q3<>"剋"),"大吉",IF(OR(P3<>"剋",Q3<>"剋"),"中吉","需注意")) -> 大吉 | S3: 木 | T3: 木 | U3: 火 | V3: =T3&U3 -> 木火 | W3: 秉持正道，睿智明理
A4: 2 | B4: 李承恩 | C4: 李 | D4: 承 | E4: 恩 | F4: 7 | G4: 8 | H4: 10 | I4: =F4+1 -> 8 | J4: =F4+G4 -> 15 | K4: =G4+H4 -> 18 | L4: =H4+1 -> 11 | M4: =F4+G4+H4 -> 25 | N4: =IF(COUNTIF(規則與試算!$A$14:$A$46,I4)+COUNTIF(規則與試算!$A$14:$A$46,J4)+COUNTIF(規則與試算!$A$14:$A$46,K4)+COUNTIF(規則與試算!$A$14:$A$46,L4)+COUNTIF(規則與試算!$A$14:$A$46,M4)=5,"全吉","有凶") -> 全吉 | O4: =INDEX(規則與試算!$D$14:$D$23,MOD(I4,10)+1)&INDEX(規則與試算!$D$14:$D$23,MOD(J4,10)+1)&INDEX(規則與試算!$D$14:$D$23,MOD(K4,10)+1) -> 金土金 | P4: =INDEX(規則與試算!$G$14:$G$38,MATCH(MID(O4,1,1)&MID(O4,2,1),規則與試算!$F$14:$F$38,0)) -> 生 | Q4: =INDEX(規則與試算!$G$14:$G$38,MATCH(MID(O4,2,1)&MID(O4,3,1),規則與試算!$F$14:$F$38,0)) -> 生 | R4: =IF(AND(P4<>"剋",Q4<>"剋"),"大吉",IF(OR(P4<>"剋",Q4<>"剋"),"中吉","需注意")) -> 大吉 | S4: 木 | T4: 金 | U4: 火 | V4: =T4&U4 -> 金火 | W4: 承接厚德，感懷恩澤
A5: 3 | B5: 李昊軒 | C5: 李 | D5: 昊 | E5: 軒 | F5: 7 | G5: 8 | H5: 10 | I5: =F5+1 -> 8 | J5: =F5+G5 -> 15 | K5: =G5+H5 -> 18 | L5: =H5+1 -> 11 | M5: =F5+G5+H5 -> 25 | N5: =IF(COUNTIF(規則與試算!$A$14:$A$46,I5)+COUNTIF(規則與試算!$A$14:$A$46,J5)+COUNTIF(規則與試算!$A$14:$A$46,K5)+COUNTIF(規則與試算!$A$14:$A$46,L5)+COUNTIF(規則與試算!$A$14:$A$46,M5)=5,"全吉","有凶") -> 全吉 | O5: =INDEX(規則與試算!$D$14:$D$23,MOD(I5,10)+1)&INDEX(規則與試算!$D$14:$D$23,MOD(J5,10)+1)&INDEX(規則與試算!$D$14:$D$23,MOD(K5,10)+1) -> 金土金 | P5: =INDEX(規則與試算!$G$14:$G$38,MATCH(MID(O5,1,1)&MID(O5,2,1),規則與試算!$F$14:$F$38,0)) -> 生 | Q5: =INDEX(規則與試算!$G$14:$G$38,MATCH(MID(O5,2,1)&MID(O5,3,1),規則與試算!$F$14:$F$38,0)) -> 生 | R5: =IF(AND(P5<>"剋",Q5<>"剋"),"大吉",IF(OR(P5<>"剋",Q5<>"剋"),"中吉","需注意")) -> 大吉 | S5: 木 | T5: 火 | U5: 土 | V5: =T5&U5 -> 火土 | W5: 天地遼闊，氣宇軒昂
A6: 4 | B6: 李明軒 | C6: 李 | D6: 明 | E6: 軒 | F6: 7 | G6: 8 | H6: 10 | I6: =F6+1 -> 8 | J6: =F6+G6 -> 15 | K6: =G6+H6 -> 18 | L6: =H6+1 -> 11 | M6: =F6+G6+H6 -> 25 | N6: =IF(COUNTIF(規則與試算!$A$14:$A$46,I6)+COUNTIF(規則與試算!$A$14:$A$46,J6)+COUNTIF(規則與試算!$A$14:$A$46,K6)+COUNTIF(規則與試算!$A$14:$A$46,L6)+COUNTIF(規則與試算!$A$14:$A$46,M6)=5,"全吉","有凶") -> 全吉 | O6: =INDEX(規則與試算!$D$14:$D$23,MOD(I6,10)+1)&INDEX(規則與試算!$D$14:$D$23,MOD(J6,10)+1)&INDEX(規則與試算!$D$14:$D$23,MOD(K6,10)+1) -> 金土金 | P6: =INDEX(規則與試算!$G$14:$G$38,MATCH(MID(O6,1,1)&MID(O6,2,1),規則與試算!$F$14:$F$38,0)) -> 生 | Q6: =INDEX(規則與試算!$G$14:$G$38,MATCH(MID(O6,2,1)&MID(O6,3,1),規則與試算!$F$14:$F$38,0)) -> 生 | R6: =IF(AND(P6<>"剋",Q6<>"剋"),"大吉",IF(OR(P6<>"剋",Q6<>"剋"),"中吉","需注意")) -> 大吉 | S6: 木 | T6: 火 | U6: 土 | V6: =T6&U6 -> 火土 | W6: 光明磊落，器宇不凡
A7: 5 | B7: 李東原 | C7: 李 | D7: 東 | E7: 原 | F7: 7 | G7: 8 | H7: 10 | I7: =F7+1 -> 8 | J7: =F7+G7 -> 15 | K7: =G7+H7 -> 18 | L7: =H7+1 -> 11 | M7: =F7+G7+H7 -> 25 | N7: =IF(COUNTIF(規則與試算!$A$14:$A$46,I7)+COUNTIF(規則與試算!$A$14:$A$46,J7)+COUNTIF(規則與試算!$A$14:$A$46,K7)+COUNTIF(規則與試算!$A$14:$A$46,L7)+COUNTIF(規則與試算!$A$14:$A$46,M7)=5,"全吉","有凶") -> 全吉 | O7: =INDEX(規則與試算!$D$14:$D$23,MOD(I7,10)+1)&INDEX(規則與試算!$D$14:$D$23,MOD(J7,10)+1)&INDEX(規則與試算!$D$14:$D$23,MOD(K7,10)+1) -> 金土金 | P7: =INDEX(規則與試算!$G$14:$G$38,MATCH(MID(O7,1,1)&MID(O7,2,1),規則與試算!$F$14:$F$38,0)) -> 生 | Q7: =INDEX(規則與試算!$G$14:$G$38,MATCH(MID(O7,2,1)&MID(O7,3,1),規則與試算!$F$14:$F$38,0)) -> 生 | R7: =IF(AND(P7<>"剋",Q7<>"剋"),"大吉",IF(OR(P7<>"剋",Q7<>"剋"),"中吉","需注意")) -> 大吉 | S7: 木 | T7: 木 | U7: 木 | V7: =T7&U7 -> 木木 | W7: 東方初曦，本原厚實
A8: 6 | B8: 李宗翰 | C8: 李 | D8: 宗 | E8: 翰 | F8: 7 | G8: 8 | H8: 16 | I8: =F8+1 -> 8 | J8: =F8+G8 -> 15 | K8: =G8+H8 -> 24 | L8: =H8+1 -> 17 | M8: =F8+G8+H8 -> 31 | N8: =IF(COUNTIF(規則與試算!$A$14:$A$46,I8)+COUNTIF(規則與試算!$A$14:$A$46,J8)+COUNTIF(規則與試算!$A$14:$A$46,K8)+COUNTIF(規則與試算!$A$14:$A$46,L8)+COUNTIF(規則與試算!$A$14:$A$46,M8)=5,"全吉","有凶") -> 全吉 | O8: =INDEX(規則與試算!$D$14:$D$23,MOD(I8,10)+1)&INDEX(規則與試算!$D$14:$D$23,MOD(J8,10)+1)&INDEX(規則與試算!$D$14:$D$23,MOD(K8,10)+1) -> 金土火 | P8: =INDEX(規則與試算!$G$14:$G$38,MATCH(MID(O8,1,1)&MID(O8,2,1),規則與試算!$F$14:$F$38,0)) -> 生 | Q8: =INDEX(規則與試算!$G$14:$G$38,MATCH(MID(O8,2,1)&MID(O8,3,1),規則與試算!$F$14:$F$38,0)) -> 生 | R8: =IF(AND(P8<>"剋",Q8<>"剋"),"大吉",IF(OR(P8<>"剋",Q8<>"剋"),"中吉","需注意")) -> 大吉 | S8: 木 | T8: 金 | U8: 水 | V8: =T8&U8 -> 金水 | W8: 宗族棟樑，文翰出眾
A9: 7 | B9: 李承勳 | C9: 李 | D9: 承 | E9: 勳 | F9: 7 | G9: 8 | H9: 16 | I9: =F9+1 -> 8 | J9: =F9+G9 -> 15 | K9: =G9+H9 -> 24 | L9: =H9+1 -> 17 | M9: =F9+G9+H9 -> 31 | N9: =IF(COUNTIF(規則與試算!$A$14:$A$46,I9)+COUNTIF(規則與試算!$A$14:$A$46,J9)+COUNTIF(規則與試算!$A$14:$A$46,K9)+COUNTIF(規則與試算!$A$14:$A$46,L9)+COUNTIF(規則與試算!$A$14:$A$46,M9)=5,"全吉","有凶") -> 全吉 | O9: =INDEX(規則與試算!$D$14:$D$23,MOD(I9,10)+1)&INDEX(規則與試算!$D$14:$D$23,MOD(J9,10)+1)&INDEX(規則與試算!$D$14:$D$23,MOD(K9,10)+1) -> 金土火 | P9: =INDEX(規則與試算!$G$14:$G$38,MATCH(MID(O9,1,1)&MID(O9,2,1),規則與試算!$F$14:$F$38,0)) -> 生 | Q9: =INDEX(規則與試算!$G$14:$G$38,MATCH(MID(O9,2,1)&MID(O9,3,1),規則與試算!$F$14:$F$38,0)) -> 生 | R9: =IF(AND(P9<>"剋",Q9<>"剋"),"大吉",IF(OR(P9<>"剋",Q9<>"剋"),"中吉","需注意")) -> 大吉 | S9: 木 | T9: 金 | U9: 金 | V9: =T9&U9 -> 金金 | W9: 承先啟後，功勳卓著
A10: 8 | B10: 李東霖 | C10: 李 | D10: 東 | E10: 霖 | F10: 7 | G10: 8 | H10: 16 | I10: =F10+1 -> 8 | J10: =F10+G10 -> 15 | K10: =G10+H10 -> 24 | L10: =H10+1 -> 17 | M10: =F10+G10+H10 -> 31 | N10: =IF(COUNTIF(規則與試算!$A$14:$A$46,I10)+COUNTIF(規則與試算!$A$14:$A$46,J10)+COUNTIF(規則與試算!$A$14:$A$46,K10)+COUNTIF(規則與試算!$A$14:$A$46,L10)+COUNTIF(規則與試算!$A$14:$A$46,M10)=5,"全吉","有凶") -> 全吉 | O10: =INDEX(規則與試算!$D$14:$D$23,MOD(I10,10)+1)&INDEX(規則與試算!$D$14:$D$23,MOD(J10,10)+1)&INDEX(規則與試算!$D$14:$D$23,MOD(K10,10)+1) -> 金土火 | P10: =INDEX(規則與試算!$G$14:$G$38,MATCH(MID(O10,1,1)&MID(O10,2,1),規則與試算!$F$14:$F$38,0)) -> 生 | Q10: =INDEX(規則與試算!$G$14:$G$38,MATCH(MID(O10,2,1)&MID(O10,3,1),規則與試算!$F$14:$F$38,0)) -> 生 | R10: =IF(AND(P10<>"剋",Q10<>"剋"),"大吉",IF(OR(P10<>"剋",Q10<>"剋"),"中吉","需注意")) -> 大吉 | S10: 木 | T10: 木 | U10: 水 | V10: =T10&U10 -> 木水 | W10: 東風化雨，甘霖潤物
A11: 9 | B11: 李承澤 | C11: 李 | D11: 承 | E11: 澤 | F11: 7 | G11: 8 | H11: 17 | I11: =F11+1 -> 8 | J11: =F11+G11 -> 15 | K11: =G11+H11 -> 25 | L11: =H11+1 -> 18 | M11: =F11+G11+H11 -> 32 | N11: =IF(COUNTIF(規則與試算!$A$14:$A$46,I11)+COUNTIF(規則與試算!$A$14:$A$46,J11)+COUNTIF(規則與試算!$A$14:$A$46,K11)+COUNTIF(規則與試算!$A$14:$A$46,L11)+COUNTIF(規則與試算!$A$14:$A$46,M11)=5,"全吉","有凶") -> 全吉 | O11: =INDEX(規則與試算!$D$14:$D$23,MOD(I11,10)+1)&INDEX(規則與試算!$D$14:$D$23,MOD(J11,10)+1)&INDEX(規則與試算!$D$14:$D$23,MOD(K11,10)+1) -> 金土土 | P11: =INDEX(規則與試算!$G$14:$G$38,MATCH(MID(O11,1,1)&MID(O11,2,1),規則與試算!$F$14:$F$38,0)) -> 生 | Q11: =INDEX(規則與試算!$G$14:$G$38,MATCH(MID(O11,2,1)&MID(O11,3,1),規則與試算!$F$14:$F$38,0)) -> 比和 | R11: =IF(AND(P11<>"剋",Q11<>"剋"),"大吉",IF(OR(P11<>"剋",Q11<>"剋"),"中吉","需注意")) -> 大吉 | S11: 木 | T11: 金 | U11: 水 | V11: =T11&U11 -> 金水 | W11: 承載恩澤，潤澤四方
A12: 10 | B12: 李秉謙 | C12: 李 | D12: 秉 | E12: 謙 | F12: 7 | G12: 8 | H12: 17 | I12: =F12+1 -> 8 | J12: =F12+G12 -> 15 | K12: =G12+H12 -> 25 | L12: =H12+1 -> 18 | M12: =F12+G12+H12 -> 32 | N12: =IF(COUNTIF(規則與試算!$A$14:$A$46,I12)+COUNTIF(規則與試算!$A$14:$A$46,J12)+COUNTIF(規則與試算!$A$14:$A$46,K12)+COUNTIF(規則與試算!$A$14:$A$46,L12)+COUNTIF(規則與試算!$A$14:$A$46,M12)=5,"全吉","有凶") -> 全吉 | O12: =INDEX(規則與試算!$D$14:$D$23,MOD(I12,10)+1)&INDEX(規則與試算!$D$14:$D$23,MOD(J12,10)+1)&INDEX(規則與試算!$D$14:$D$23,MOD(K12,10)+1) -> 金土土 | P12: =INDEX(規則與試算!$G$14:$G$38,MATCH(MID(O12,1,1)&MID(O12,2,1),規則與試算!$F$14:$F$38,0)) -> 生 | Q12: =INDEX(規則與試算!$G$14:$G$38,MATCH(MID(O12,2,1)&MID(O12,3,1),規則與試算!$F$14:$F$38,0)) -> 比和 | R12: =IF(AND(P12<>"剋",Q12<>"剋"),"大吉",IF(OR(P12<>"剋",Q12<>"剋"),"中吉","需注意")) -> 大吉 | S12: 木 | T12: 木 | U12: 金 | V12: =T12&U12 -> 木金 | W12: 秉性正直，謙沖自牧
A13: 11 | B13: 李昊駿 | C13: 李 | D13: 昊 | E13: 駿 | F13: 7 | G13: 8 | H13: 17 | I13: =F13+1 -> 8 | J13: =F13+G13 -> 15 | K13: =G13+H13 -> 25 | L13: =H13+1 -> 18 | M13: =F13+G13+H13 -> 32 | N13: =IF(COUNTIF(規則與試算!$A$14:$A$46,I13)+COUNTIF(規則與試算!$A$14:$A$46,J13)+COUNTIF(規則與試算!$A$14:$A$46,K13)+COUNTIF(規則與試算!$A$14:$A$46,L13)+COUNTIF(規則與試算!$A$14:$A$46,M13)=5,"全吉","有凶") -> 全吉 | O13: =INDEX(規則與試算!$D$14:$D$23,MOD(I13,10)+1)&INDEX(規則與試算!$D$14:$D$23,MOD(J13,10)+1)&INDEX(規則與試算!$D$14:$D$23,MOD(K13,10)+1) -> 金土土 | P13: =INDEX(規則與試算!$G$14:$G$38,MATCH(MID(O13,1,1)&MID(O13,2,1),規則與試算!$F$14:$F$38,0)) -> 生 | Q13: =INDEX(規則與試算!$G$14:$G$38,MATCH(MID(O13,2,1)&MID(O13,3,1),規則與試算!$F$14:$F$38,0)) -> 比和 | R13: =IF(AND(P13<>"剋",Q13<>"剋"),"大吉",IF(OR(P13<>"剋",Q13<>"剋"),"中吉","需注意")) -> 大吉 | S13: 木 | T13: 火 | U13: 火 | V13: =T13&U13 -> 火火 | W13: 胸襟廣闊，駿馬奔騰
A14: 12 | B14: 李冠廷 | C14: 李 | D14: 冠 | E14: 廷 | F14: 7 | G14: 9 | H14: 7 | I14: =F14+1 -> 8 | J14: =F14+G14 -> 16 | K14: =G14+H14 -> 16 | L14: =H14+1 -> 8 | M14: =F14+G14+H14 -> 23 | N14: =IF(COUNTIF(規則與試算!$A$14:$A$46,I14)+COUNTIF(規則與試算!$A$14:$A$46,J14)+COUNTIF(規則與試算!$A$14:$A$46,K14)+COUNTIF(規則與試算!$A$14:$A$46,L14)+COUNTIF(規則與試算!$A$14:$A$46,M14)=5,"全吉","有凶") -> 全吉 | O14: =INDEX(規則與試算!$D$14:$D$23,MOD(I14,10)+1)&INDEX(規則與試算!$D$14:$D$23,MOD(J14,10)+1)&INDEX(規則與試算!$D$14:$D$23,MOD(K14,10)+1) -> 金土土 | P14: =INDEX(規則與試算!$G$14:$G$38,MATCH(MID(O14,1,1)&MID(O14,2,1),規則與試算!$F$14:$F$38,0)) -> 生 | Q14: =INDEX(規則與試算!$G$14:$G$38,MATCH(MID(O14,2,1)&MID(O14,3,1),規則與試算!$F$14:$F$38,0)) -> 比和 | R14: =IF(AND(P14<>"剋",Q14<>"剋"),"大吉",IF(OR(P14<>"剋",Q14<>"剋"),"中吉","需注意")) -> 大吉 | S14: 木 | T14: 金 | U14: 木 | V14: =T14&U14 -> 金木 | W14: 才冠群倫，立身端正
... A52: 50 | B52: 李豐志 | C52: 李 | D52: 豐 | E52: 志 | F52: 7 | G52: 18 | H52: 7 | I52: =F52+1 -> 8 | J52: =F52+G52 -> 25 | K52: =G52+H52 -> 25 | L52: =H52+1 -> 8 | M52: =F52+G52+H52 -> 32 | N52: =IF(COUNTIF(規則與試算!$A$14:$A$46,I52)+COUNTIF(規則與試算!$A$14:$A$46,J52)+COUNTIF(規則與試算!$A$14:$A$46,K52)+COUNTIF(規則與試算!$A$14:$A$46,L52)+COUNTIF(規則與試算!$A$14:$A$46,M52)=5,"全吉","有凶") -> 全吉 | O52: =INDEX(規則與試算!$D$14:$D$23,MOD(I52,10)+1)&INDEX(規則與試算!$D$14:$D$23,MOD(J52,10)+1)&INDEX(規則與試算!$D$14:$D$23,MOD(K52,10)+1) -> 金土土 | P52: =INDEX(規則與試算!$G$14:$G$38,MATCH(MID(O52,1,1)&MID(O52,2,1),規則與試算!$F$14:$F$38,0)) -> 生 | Q52: =INDEX(規則與試算!$G$14:$G$38,MATCH(MID(O52,2,1)&MID(O52,3,1),規則與試算!$F$14:$F$38,0)) -> 比和 | R52: =IF(AND(P52<>"剋",Q52<>"剋"),"大吉",IF(OR(P52<>"剋",Q52<>"剋"),"中吉","需注意")) -> 大吉 | S52: 木 | T52: 火 | U52: 火 | V52: =T52&U52 -> 火火 | W52: 豐盈厚實，志向遠大

Sheet 女生名單
A1: 女生名單
A2: 序號 | B2: 姓名 | C2: 姓 | D2: 名1 | E2: 名2 | F2: 姓劃 | G2: 名1劃 | H2: 名2劃 | I2: 天格 | J2: 人格 | K2: 地格 | L2: 外格 | M2: 總格 | N2: 五格判定 | O2: 三才配置 | P2: 天人關係 | Q2: 人地關係 | R2: 三才吉凶 | S2: 姓部首五行 | T2: 名1部首五行 | U2: 名2部首五行 | V2: 名字補五行 | W2: 字義寓意
A3: 1 | B3: 李佳恬 | C3: 李 | D3: 佳 | E3: 恬 | F3: 7 | G3: 8 | H3: 10 | I3: =F3+1 -> 8 | J3: =F3+G3 -> 15 | K3: =G3+H3 -> 18 | L3: =H3+1 -> 11 | M3: =F3+G3+H3 -> 25 | N3: =IF(COUNTIF(規則與試算!$A$14:$A$46,I3)+COUNTIF(規則與試算!$A$14:$A$46,J3)+COUNTIF(規則與試算!$A$14:$A$46,K3)+COUNTIF(規則與試算!$A$14:$A$46,L3)+COUNTIF(規則與試算!$A$14:$A$46,M3)=5,"全吉","有凶") -> 全吉 | O3: =INDEX(規則與試算!$D$14:$D$23,MOD(I3,10)+1)&INDEX(規則與試算!$D$14:$D$23,MOD(J3,10)+1)&INDEX(規則與試算!$D$14:$D$23,MOD(K3,10)+1) -> 金土金 | P3: =INDEX(規則與試算!$G$14:$G$38,MATCH(MID(O3,1,1)&MID(O3,2,1),規則與試算!$F$14:$F$38,0)) -> 生 | Q3: =INDEX(規則與試算!$G$14:$G$38,MATCH(MID(O3,2,1)&MID(O3,3,1),規則與試算!$F$14:$F$38,0)) -> 生 | R3: =IF(AND(P3<>"剋",Q3<>"剋"),"大吉",IF(OR(P3<>"剋",Q3<>"剋"),"中吉","需注意")) -> 大吉 | S3: 木 | T3: 木 | U3: 火 | V3: =T3&U3 -> 木火 | W3: 美好佳善，恬靜安然
A4: 2 | B4: 李欣芮 | C4: 李 | D4: 欣 | E4: 芮 | F4: 7 | G4: 8 | H4: 10 | I4: =F4+1 -> 8 | J4: =F4+G4 -> 15 | K4: =G4+H4 -> 18 | L4: =H4+1 -> 11 | M4: =F4+G4+H4 -> 25 | N4: =IF(COUNTIF(規則與試算!$A$14:$A$46,I4)+COUNTIF(規則與試算!$A$14:$A$46,J4)+COUNTIF(規則與試算!$A$14:$A$46,K4)+COUNTIF(規則與試算!$A$14:$A$46,L4)+COUNTIF(規則與試算!$A$14:$A$46,M4)=5,"全吉","有凶") -> 全吉 | O4: =INDEX(規則與試算!$D$14:$D$23,MOD(I4,10)+1)&INDEX(規則與試算!$D$14:$D$23,MOD(J4,10)+1)&INDEX(規則與試算!$D$14:$D$23,MOD(K4,10)+1) -> 金土金 | P4: =INDEX(規則與試算!$G$14:$G$38,MATCH(MID(O4,1,1)&MID(O4,2,1),規則與試算!$F$14:$F$38,0)) -> 生 | Q4: =INDEX(規則與試算!$G$14:$G$38,MATCH(MID(O4,2,1)&MID(O4,3,1),規則與試算!$F$14:$F$38,0)) -> 生 | R4: =IF(AND(P4<>"剋",Q4<>"剋"),"大吉",IF(OR(P4<>"剋",Q4<>"剋"),"中吉","需注意")) -> 大吉 | S4: 木 | T4: 木 | U4: 木 | V4: =T4&U4 -> 木木 | W4: 欣欣向榮，草木初生
A5: 3 | B5: 李宜庭 | C5: 李 | D5: 宜 | E5: 庭 | F5: 7 | G5: 8 | H5: 10 | I5: =F5+1 -> 8 | J5: =F5+G5 -> 15 | K5: =G5+H5 -> 18 | L5: =H5+1 -> 11 | M5: =F5+G5+H5 -> 25 | N5: =IF(COUNTIF(規則與試算!$A$14:$A$46,I5)+COUNTIF(規則與試算!$A$14:$A$46,J5)+COUNTIF(規則與試算!$A$14:$A$46,K5)+COUNTIF(規則與試算!$A$14:$A$46,L5)+COUNTIF(規則與試算!$A$14:$A$46,M5)=5,"全吉","有凶") -> 全吉 | O5: =INDEX(規則與試算!$D$14:$D$23,MOD(I5,10)+1)&INDEX(規則與試算!$D$14:$D$23,MOD(J5,10)+1)&INDEX(規則與試算!$D$14:$D$23,MOD(K5,10)+1) -> 金土金 | P5: =INDEX(規則與試算!$G$14:$G$38,MATCH(MID(O5,1,1)&MID(O5,2,1),規則與試算!$F$14:$F$38,0)) -> 生 | Q5: =INDEX(規則與試算!$G$14:$G$38,MATCH(MID(O5,2,1)&MID(O5,3,1),規則與試算!$F$14:$F$38,0)) -> 生 | R5: =IF(AND(P5<>"剋",Q5<>"剋"),"大吉",IF(OR(P5<>"剋",Q5<>"剋"),"中吉","需注意")) -> 大吉 | S5: 木 | T5: 土 | U5: 火 | V5: =T5&U5 -> 土火 | W5: 溫良合宜，家庭和睦
A6: 4 | B6: 李佳芸 | C6: 李 | D6: 佳 | E6: 芸 | F6: 7 | G6: 8 | H6: 10 | I6: =F6+1 -> 8 | J6: =F6+G6 -> 15 | K6: =G6+H6 -> 18 | L6: =H6+1 -> 11 | M6: =F6+G6+H6 -> 25 | N6: =IF(COUNTIF(規則與試算!$A$14:$A$46,I6)+COUNTIF(規則與試算!$A$14:$A$46,J6)+COUNTIF(規則與試算!$A$14:$A$46,K6)+COUNTIF(規則與試算!$A$14:$A$46,L6)+COUNTIF(規則與試算!$A$14:$A$46,M6)=5,"全吉","有凶") -> 全吉 | O6: =INDEX(規則與試算!$D$14:$D$23,MOD(I6,10)+1)&INDEX(規則與試算!$D$14:$D$23,MOD(J6,10)+1)&INDEX(規則與試算!$D$14:$D$23,MOD(K6,10)+1) -> 金土金 | P6: =INDEX(規則與試算!$G$14:$G$38,MATCH(MID(O6,1,1)&MID(O6,2,1),規則與試算!$F$14:$F$38,0)) -> 生 | Q6: =INDEX(規則與試算!$G$14:$G$38,MATCH(MID(O6,2,1)&MID(O6,3,1),規則與試算!$F$14:$F$38,0)) -> 生 | R6: =IF(AND(P6<>"剋",Q6<>"剋"),"大吉",IF(OR(P6<>"剋",Q6<>"剋"),"中吉","需注意")) -> 大吉 | S6: 木 | T6: 木 | U6: 木 | V6: =T6&U6 -> 木木 | W6: 佳人如玉，芸香書卷
A7: 5 | B7: 李欣恬 | C7: 李 | D7: 欣 | E7: 恬 | F7: 7 | G7: 8 | H7: 10 | I7: =F7+1 -> 8 | J7: =F7+G7 -> 15 | K7: =G7+H7 -> 18 | L7: =H7+1 -> 11 | M7: =F7+G7+H7 -> 25 | N7: =IF(COUNTIF(規則與試算!$A$14:$A$46,I7)+COUNTIF(規則與試算!$A$14:$A$46,J7)+COUNTIF(規則與試算!$A$14:$A$46,K7)+COUNTIF(規則與試算!$A$14:$A$46,L7)+COUNTIF(規則與試算!$A$14:$A$46,M7)=5,"全吉","有凶") -> 全吉 | O7: =INDEX(規則與試算!$D$14:$D$23,MOD(I7,10)+1)&INDEX(規則與試算!$D$14:$D$23,MOD(J7,10)+1)&INDEX(規則與試算!$D$14:$D$23,MOD(K7,10)+1) -> 金土金 | P7: =INDEX(規則與試算!$G$14:$G$38,MATCH(MID(O7,1,1)&MID(O7,2,1),規則與試算!$F$14:$F$38,0)) -> 生 | Q7: =INDEX(規則與試算!$G$14:$G$38,MATCH(MID(O7,2,1)&MID(O7,3,1),規則與試算!$F$14:$F$38,0)) -> 生 | R7: =IF(AND(P7<>"剋",Q7<>"剋"),"大吉",IF(OR(P7<>"剋",Q7<>"剋"),"中吉","需注意")) -> 大吉 | S7: 木 | T7: 木 | U7: 火 | V7: =T7&U7 -> 木火 | W7: 欣悅開朗，恬淡自適
A8: 6 | B8: 李佳蓁 | C8: 李 | D8: 佳 | E8: 蓁 | F8: 7 | G8: 8 | H8: 16 | I8: =F8+1 -> 8 | J8: =F8+G8 -> 15 | K8: =G8+H8 -> 24 | L8: =H8+1 -> 17 | M8: =F8+G8+H8 -> 31 | N8: =IF(COUNTIF(規則與試算!$A$14:$A$46,I8)+COUNTIF(規則與試算!$A$14:$A$46,J8)+COUNTIF(規則與試算!$A$14:$A$46,K8)+COUNTIF(規則與試算!$A$14:$A$46,L8)+COUNTIF(規則與試算!$A$14:$A$46,M8)=5,"全吉","有凶") -> 全吉 | O8: =INDEX(規則與試算!$D$14:$D$23,MOD(I8,10)+1)&INDEX(規則與試算!$D$14:$D$23,MOD(J8,10)+1)&INDEX(規則與試算!$D$14:$D$23,MOD(K8,10)+1) -> 金土火 | P8: =INDEX(規則與試算!$G$14:$G$38,MATCH(MID(O8,1,1)&MID(O8,2,1),規則與試算!$F$14:$F$38,0)) -> 生 | Q8: =INDEX(規則與試算!$G$14:$G$38,MATCH(MID(O8,2,1)&MID(O8,3,1),規則與試算!$F$14:$F$38,0)) -> 生 | R8: =IF(AND(P8<>"剋",Q8<>"剋"),"大吉",IF(OR(P8<>"剋",Q8<>"剋"),"中吉","需注意")) -> 大吉 | S8: 木 | T8: 木 | U8: 木 | V8: =T8&U8 -> 木木 | W8: 佳美出眾，草木蓁蓁
A9: 7 | B9: 李欣穎 | C9: 李 | D9: 欣 | E9: 穎 | F9: 7 | G9: 8 | H9: 16 | I9: =F9+1 -> 8 | J9: =F9+G9 -> 15 | K9: =G9+H9 -> 24 | L9: =H9+1 -> 17 | M9: =F9+G9+H9 -> 31 | N9: =IF(COUNTIF(規則與試算!$A$14:$A$46,I9)+COUNTIF(規則與試算!$A$14:$A$46,J9)+COUNTIF(規則與試算!$A$14:$A$46,K9)+COUNTIF(規則與試算!$A$14:$A$46,L9)+COUNTIF(規則與試算!$A$14:$A$46,M9)=5,"全吉","有凶") -> 全吉 | O9: =INDEX(規則與試算!$D$14:$D$23,MOD(I9,10)+1)&INDEX(規則與試算!$D$14:$D$23,MOD(J9,10)+1)&INDEX(規則與試算!$D$14:$D$23,MOD(K9,10)+1) -> 金土火 | P9: =INDEX(規則與試算!$G$14:$G$38,MATCH(MID(O9,1,1)&MID(O9,2,1),規則與試算!$F$14:$F$38,0)) -> 生 | Q9: =INDEX(規則與試算!$G$14:$G$38,MATCH(MID(O9,2,1)&MID(O9,3,1),規則與試算!$F$14:$F$38,0)) -> 生 | R9: =IF(AND(P9<>"剋",Q9<>"剋"),"大吉",IF(OR(P9<>"剋",Q9<>"剋"),"中吉","需注意")) -> 大吉 | S9: 木 | T9: 木 | U9: 木 | V9: =T9&U9 -> 木木 | W9: 欣然向上，聰穎過人
A10: 8 | B10: 李宜蓁 | C10: 李 | D10: 宜 | E10: 蓁 | F10: 7 | G10: 8 | H10: 16 | I10: =F10+1 -> 8 | J10: =F10+G10 -> 15 | K10: =G10+H10 -> 24 | L10: =H10+1 -> 17 | M10: =F10+G10+H10 -> 31 | N10: =IF(COUNTIF(規則與試算!$A$14:$A$46,I10)+COUNTIF(規則與試算!$A$14:$A$46,J10)+COUNTIF(規則與試算!$A$14:$A$46,K10)+COUNTIF(規則與試算!$A$14:$A$46,L10)+COUNTIF(規則與試算!$A$14:$A$46,M10)=5,"全吉","有凶") -> 全吉 | O10: =INDEX(規則與試算!$D$14:$D$23,MOD(I10,10)+1)&INDEX(規則與試算!$D$14:$D$23,MOD(J10,10)+1)&INDEX(規則與試算!$D$14:$D$23,MOD(K10,10)+1) -> 金土火 | P10: =INDEX(規則與試算!$G$14:$G$38,MATCH(MID(O10,1,1)&MID(O10,2,1),規則與試算!$F$14:$F$38,0)) -> 生 | Q10: =INDEX(規則與試算!$G$14:$G$38,MATCH(MID(O10,2,1)&MID(O10,3,1),規則與試算!$F$14:$F$38,0)) -> 生 | R10: =IF(AND(P10<>"剋",Q10<>"剋"),"大吉",IF(OR(P10<>"剋",Q10<>"剋"),"中吉","需注意")) -> 大吉 | S10: 木 | T10: 土 | U10: 木 | V10: =T10&U10 -> 土木 | W10: 合宜大方，生機盎然
A11: 9 | B11: 李佳霏 | C11: 李 | D11: 佳 | E11: 霏 | F11: 7 | G11: 8 | H11: 16 | I11: =F11+1 -> 8 | J11: =F11+G11 -> 15 | K11: =G11+H11 -> 24 | L11: =H11+1 -> 17 | M11: =F11+G11+H11 -> 31 | N11: =IF(COUNTIF(規則與試算!$A$14:$A$46,I11)+COUNTIF(規則與試算!$A$14:$A$46,J11)+COUNTIF(規則與試算!$A$14:$A$46,K11)+COUNTIF(規則與試算!$A$14:$A$46,L11)+COUNTIF(規則與試算!$A$14:$A$46,M11)=5,"全吉","有凶") -> 全吉 | O11: =INDEX(規則與試算!$D$14:$D$23,MOD(I11,10)+1)&INDEX(規則與試算!$D$14:$D$23,MOD(J11,10)+1)&INDEX(規則與試算!$D$14:$D$23,MOD(K11,10)+1) -> 金土火 | P11: =INDEX(規則與試算!$G$14:$G$38,MATCH(MID(O11,1,1)&MID(O11,2,1),規則與試算!$F$14:$F$38,0)) -> 生 | Q11: =INDEX(規則與試算!$G$14:$G$38,MATCH(MID(O11,2,1)&MID(O11,3,1),規則與試算!$F$14:$F$38,0)) -> 生 | R11: =IF(AND(P11<>"剋",Q11<>"剋"),"大吉",IF(OR(P11<>"剋",Q11<>"剋"),"中吉","需注意")) -> 大吉 | S11: 木 | T11: 木 | U11: 水 | V11: =T11&U11 -> 木水 | W11: 佳氣氤氳，雨雪霏霏
A12: 10 | B12: 李佳禧 | C12: 李 | D12: 佳 | E12: 禧 | F12: 7 | G12: 8 | H12: 17 | I12: =F12+1 -> 8 | J12: =F12+G12 -> 15 | K12: =G12+H12 -> 25 | L12: =H12+1 -> 18 | M12: =F12+G12+H12 -> 32 | N12: =IF(COUNTIF(規則與試算!$A$14:$A$46,I12)+COUNTIF(規則與試算!$A$14:$A$46,J12)+COUNTIF(規則與試算!$A$14:$A$46,K12)+COUNTIF(規則與試算!$A$14:$A$46,L12)+COUNTIF(規則與試算!$A$14:$A$46,M12)=5,"全吉","有凶") -> 全吉 | O12: =INDEX(規則與試算!$D$14:$D$23,MOD(I12,10)+1)&INDEX(規則與試算!$D$14:$D$23,MOD(J12,10)+1)&INDEX(規則與試算!$D$14:$D$23,MOD(K12,10)+1) -> 金土土 | P12: =INDEX(規則與試算!$G$14:$G$38,MATCH(MID(O12,1,1)&MID(O12,2,1),規則與試算!$F$14:$F$38,0)) -> 生 | Q12: =INDEX(規則與試算!$G$14:$G$38,MATCH(MID(O12,2,1)&MID(O12,3,1),規則與試算!$F$14:$F$38,0)) -> 比和 | R12: =IF(AND(P12<>"剋",Q12<>"剋"),"大吉",IF(OR(P12<>"剋",Q12<>"剋"),"中吉","需注意")) -> 大吉 | S12: 木 | T12: 木 | U12: 土 | V12: =T12&U12 -> 木土 | W12: 美善吉祥，福禧綿長
A13: 11 | B13: 李欣霞 | C13: 李 | D13: 欣 | E13: 霞 | F13: 7 | G13: 8 | H13: 17 | I13: =F13+1 -> 8 | J13: =F13+G13 -> 15 | K13: =G13+H13 -> 25 | L13: =H13+1 -> 18 | M13: =F13+G13+H13 -> 32 | N13: =IF(COUNTIF(規則與試算!$A$14:$A$46,I13)+COUNTIF(規則與試算!$A$14:$A$46,J13)+COUNTIF(規則與試算!$A$14:$A$46,K13)+COUNTIF(規則與試算!$A$14:$A$46,L13)+COUNTIF(規則與試算!$A$14:$A$46,M13)=5,"全吉","有凶") -> 全吉 | O13: =INDEX(規則與試算!$D$14:$D$23,MOD(I13,10)+1)&INDEX(規則與試算!$D$14:$D$23,MOD(J13,10)+1)&INDEX(規則與試算!$D$14:$D$23,MOD(K13,10)+1) -> 金土土 | P13: =INDEX(規則與試算!$G$14:$G$38,MATCH(MID(O13,1,1)&MID(O13,2,1),規則與試算!$F$14:$F$38,0)) -> 生 | Q13: =INDEX(規則與試算!$G$14:$G$38,MATCH(MID(O13,2,1)&MID(O13,3,1),規則與試算!$F$14:$F$38,0)) -> 比和 | R13: =IF(AND(P13<>"剋",Q13<>"剋"),"大吉",IF(OR(P13<>"剋",Q13<>"剋"),"中吉","需注意")) -> 大吉 | S13: 木 | T13: 木 | U13: 水 | V13: =T13&U13 -> 木水 | W13: 欣喜開朗，霞光燦爛
A14: 12 | B14: 李思妤 | C14: 李 | D14: 思 | E14: 妤 | F14: 7 | G14: 9 | H14: 7 | I14: =F14+1 -> 8 | J14: =F14+G14 -> 16 | K14: =G14+H14 -> 16 | L14: =H14+1 -> 8 | M14: =F14+G14+H14 -> 23 | N14: =IF(COUNTIF(規則與試算!$A$14:$A$46,I14)+COUNTIF(規則與試算!$A$14:$A$46,J14)+COUNTIF(規則與試算!$A$14:$A$46,K14)+COUNTIF(規則與試算!$A$14:$A$46,L14)+COUNTIF(規則與試算!$A$14:$A$46,M14)=5,"全吉","有凶") -> 全吉 | O14: =INDEX(規則與試算!$D$14:$D$23,MOD(I14,10)+1)&INDEX(規則與試算!$D$14:$D$23,MOD(J14,10)+1)&INDEX(規則與試算!$D$14:$D$23,MOD(K14,10)+1) -> 金土土 | P14: =INDEX(規則與試算!$G$14:$G$38,MATCH(MID(O14,1,1)&MID(O14,2,1),規則與試算!$F$14:$F$38,0)) -> 生 | Q14: =INDEX(規則與試算!$G$14:$G$38,MATCH(MID(O14,2,1)&MID(O14,3,1),規則與試算!$F$14:$F$38,0)) -> 比和 | R14: =IF(AND(P14<>"剋",Q14<>"剋"),"大吉",IF(OR(P14<>"剋",Q14<>"剋"),"中吉","需注意")) -> 大吉 | S14: 木 | T14: 火 | U14: 水 | V14: =T14&U14 -> 火水 | W14: 思慮周詳，秀外慧中
... A52: 50 | B52: 李梓語 | C52: 李 | D52: 梓 | E52: 語 | F52: 7 | G52: 11 | H52: 14 | I52: =F52+1 -> 8 | J52: =F52+G52 -> 18 | K52: =G52+H52 -> 25 | L52: =H52+1 -> 15 | M52: =F52+G52+H52 -> 32 | N52: =IF(COUNTIF(規則與試算!$A$14:$A$46,I52)+COUNTIF(規則與試算!$A$14:$A$46,J52)+COUNTIF(規則與試算!$A$14:$A$46,K52)+COUNTIF(規則與試算!$A$14:$A$46,L52)+COUNTIF(規則與試算!$A$14:$A$46,M52)=5,"全吉","有凶") -> 全吉 | O52: =INDEX(規則與試算!$D$14:$D$23,MOD(I52,10)+1)&INDEX(規則與試算!$D$14:$D$23,MOD(J52,10)+1)&INDEX(規則與試算!$D$14:$D$23,MOD(K52,10)+1) -> 金金土 | P52: =INDEX(規則與試算!$G$14:$G$38,MATCH(MID(O52,1,1)&MID(O52,2,1),規則與試算!$F$14:$F$38,0)) -> 比和 | Q52: =INDEX(規則與試算!$G$14:$G$38,MATCH(MID(O52,2,1)&MID(O52,3,1),規則與試算!$F$14:$F$38,0)) -> 生 | R52: =IF(AND(P52<>"剋",Q52<>"剋"),"大吉",IF(OR(P52<>"剋",Q52<>"剋"),"中吉","需注意")) -> 大吉 | S52: 木 | T52: 木 | U52: 金 | V52: =T52&U52 -> 木金 | W52: 梓材成器，妙語如珠

Sheet 規則與試算
A1: 李姓命名候選名單 — 規則、資料來源與自訂試算
A3: • 資料來源：本工作簿的「姓劃／名1劃／名2劃」為康熙字典筆劃，取自命名工具專案的 kangxi-data.js（63,696 字）。
A4: • 部首五行取自同專案 script.js 的 CHAR_RADICAL_DB（依字形部首判定，用於八字補救），與五格的「數理五行」（依筆劃尾數）不同。
A5: • 五格公式：天格＝姓＋1；人格＝姓＋名1；地格＝名1＋名2；外格＝名2＋1；總格＝姓＋名1＋名2（單姓兩字名適用）。
A6: • 三才吉凶：天人、人地兩組關係皆非「剋」＝大吉；其一為「剋」＝中吉；兩者皆「剋」＝需注意。
A7: • 全部 100 個名字均為「五格全吉 ＋ 三才大吉」，取自「李」姓 36 組合格筆劃組合中的 15 組大吉組合。
A8: • 假設：姓氏固定為「李」（康熙 7 劃，天格 8 為吉數・金）。若換姓氏，改下方試算區的姓劃即可重算。
A9: • 尚未納入八字／紫微：使用者未提供出生時辰，故無法判斷五行喜忌；請用「名字補五行」欄位對照八字所缺的五行來挑選。
A10: • 字義寓意欄為一般字義解讀，供命名參考，非命理判定結果。
A12: ■ 81 數吉數清單（33 個） | C12: ■ 數理五行（依筆劃尾數） | F12: ■ 五行生剋對照 | I12: ■ 自訂試算（只需修改黃底儲存格）
A13: 劃數 | C13: 尾數 | D13: 五行 | F13: 組合 | G13: 關係 | I13: 欄位 | J13: 值
A14: 1 | C14: 0 | D14: 水 | F14: 木木 | G14: 比和 | I14: 姓劃（可改） | J14: 7
A15: 3 | C15: 1 | D15: 木 | F15: 木火 | G15: 生 | I15: 名1劃（可改） | J15: 9
A16: 5 | C16: 2 | D16: 木 | F16: 木土 | G16: 剋 | I16: 名2劃（可改） | J16: 16
A17: 6 | C17: 3 | D17: 火 | F17: 木金 | G17: 剋 | I17: 天格 | J17: =J14+1 -> 8
A18: 7 | C18: 4 | D18: 火 | F18: 木水 | G18: 生 | I18: 人格 | J18: =J14+J15 -> 16
A19: 8 | C19: 5 | D19: 土 | F19: 火木 | G19: 生 | I19: 地格 | J19: =J15+J16 -> 25
A20: 11 | C20: 6 | D20: 土 | F20: 火火 | G20: 比和 | I20: 外格 | J20: =J16+1 -> 17
A21: 13 | C21: 7 | D21: 金 | F21: 火土 | G21: 生 | I21: 總格 | J21: =J14+J15+J16 -> 32
A22: 15 | C22: 8 | D22: 金 | F22: 火金 | G22: 剋 | I22: 五格判定 | J22: =IF(COUNTIF(規則與試算!$A$14:$A$46,J17)+COUNTIF(規則與試算!$A$14:$A$46,J18)+COUNTIF(規則與試算!$A$14:$A$46,J19)+COUNTIF(規則與試算!$A$14:$A$46,J20)+COUNTIF(規則與試算!$A$14:$A$46,J21)=5,"全吉","有凶") -> 全吉
A23: 16 | C23: 9 | D23: 水 | F23: 火水 | G23: 剋 | I23: 三才配置 | J23: =INDEX(規則與試算!$D$14:$D$23,MOD(J17,10)+1)&INDEX(規則與試算!$D$14:$D$23,MOD(J18,10)+1)&INDEX(規則與試算!$D$14:$D$23,MOD(J19,10)+1) -> 金土土
A24: 17 | F24: 土木 | G24: 剋 | I24: 天人關係 | J24: =INDEX(規則與試算!$G$14:$G$38,MATCH(MID(J23,1,1)&MID(J23,2,1),規則與試算!$F$14:$F$38,0)) -> 生
A25: 18 | F25: 土火 | G25: 生 | I25: 人地關係 | J25: =INDEX(規則與試算!$G$14:$G$38,MATCH(MID(J23,2,1)&MID(J23,3,1),規則與試算!$F$14:$F$38,0)) -> 比和
A26: 21 | F26: 土土 | G26: 比和 | I26: 三才吉凶 | J26: =IF(AND(J24<>"剋",J25<>"剋"),"大吉",IF(OR(J24<>"剋",J25<>"剋"),"中吉","需注意")) -> 大吉
A27: 23 | F27: 土金 | G27: 生 | I27: 範例：7 / 9 / 16 即「李柏翰」，結果應為 全吉・金土土・大吉
A28: 24 | F28: 土水 | G28: 剋
A29: 25 | F29: 金木 | G29: 剋 | I29: 色彩圖例：藍字＝輸入的康熙筆劃（可改）｜黃底＝試算輸入格｜黑字＝公式自動計算
A30: 31 | F30: 金火 | G30: 剋
A31: 32 | F31: 金土 | G31: 生
A32: 33 | F32: 金金 | G32: 比和
A33: 35 | F33: 金水 | G33: 生
A34: 37 | F34: 水木 | G34: 生
A35: 39 | F35: 水火 | G35: 剋
A36: 41 | F36: 水土 | G36: 剋
A37: 45 | F37: 水金 | G37: 生
A38: 47 | F38: 水水 | G38: 比和
A39: 48
A40: 52
A41: 63
A42: 65
...
